Workbook

Sheet Master
A1: 246 South 2nd Street · Master Pro Forma
A2: 246 South 2nd Street on its own 3,100 sf lot in R6 with a commercial overlay: 8 stories at 85 ft (13'-11" ground floor, 11 ft 2nd floor, 10 ft above), plus a cellar and a private roof. 9 condos (8 market-rate and one affordable homeownership unit), 6,879 sellable sf; commercial on the 1st and 2nd floors (4,333 sf sellable) plus 1,857 sf in the cellar; Zone Green (ULEB) 5% exclusion; no air rights or certificates; all-electric. Residential priced at $1,450/sf (base, placeholder until comps).
A3: Every figure here is pulled from the Finance, Hard Costs and Soft Costs sheets (green). Change inputs on those sheets, not here.
A5: PROGRAM
A6: Condo units | B6: ='Hard Costs'!$C$12 -> 9
A7: Net sellable residential sf, as designed | B7: ='Hard Costs'!$C$10 -> 6879 | E7: The real area. Costs and the $ / sellable sf column use it.
A8: Sellable sf used for revenue | B8: ='Rev & Unit-by-Unit'!$I$27 -> 6879 | E8: Includes the owner's sellable-area adjustment (revenue only) on the Rev & Unit-by-Unit sheet.
A9: Commercial at grade (1st floor), sf | B9: ='Hard Costs'!$C$9 -> 1717
A10: Commercial, 2nd floor, sf | B10: ='Hard Costs'!$C$22 -> 2616
A11: Cellar commercial and community facility, sf | B11: ='Hard Costs'!$C$17 -> 1857 | E11: Sold with the commercial condo. Not zoning floor area.
A12: Gross floor area above grade | B12: ='Hard Costs'!$C$6 -> 14518 | E12: Plus a cellar; see the Hard Costs sheet.
A13: Zoning floor area check (total, with the Zone Green exclusion) | B13: ='Hard Costs'!C49 -> PASS | E13: From the Hard Costs sheet: 11,911 of 14,880 sf counted.
A14: Market-rate residential floor area check | B14: ='Hard Costs'!C50 -> PASS | E14: 6,819 counted of 6,820 allowed (2.2 FAR), after the Zone Green exclusion.
A15: Height check: 85 ft against the 85 ft limit | B15: ='Hard Costs'!C54 -> PASS
A17: REVENUE
B18: Amount | C18: $ / sellable sf | D18: % of cost | E18: Notes
A19: Residential condo sales, gross | B19: ='Rev & Unit-by-Unit'!$M$27 -> 9030450 | C19: =B19/$B$7 -> 1312.7562 | E19: Sum of the unit prices on the Rev & Unit-by-Unit sheet.
A20: Average condo price, all units | B20: ='Rev & Unit-by-Unit'!$N$27 -> 1312.7562 | E20: $ per sellable sf used for revenue.
A21: Price, standard units | B21: ='Rev & Unit-by-Unit'!$G$6 -> 1450 | E21: Before any unit premium, discount or asking-price override.
A22: Commercial condo sale value | B22: ='Rev & Unit-by-Unit'!$G$42 -> 5095798 | C22: =B22/($B$9+$B$10) -> 1176.0438 | E22: Value per sf of commercial above grade (1st and 2nd floors). Rent, vacancy, expenses and cap rate on the Rev & Unit-by-Unit sheet.
A23: Gross revenue | B23: =B19+B22 -> 14126248 | C23: =B23/$B$7 -> 2053.5322
A24: Less condo sale costs | B24: =-'Rev & Unit-by-Unit'!$M$61 -> -518219.21 | C24: =B24/$B$7 -> -75.33351 | E24: Commissions, transfer taxes paid by the sponsor, closing costs.
A25: Less commercial sale costs | B25: =-'Rev & Unit-by-Unit'!$M$68 -> -498114.25 | C25: =B25/$B$7 -> -72.410853
A26: Less end-loan packages and lender releases | B26: =-'Rev & Unit-by-Unit'!$M$74 -> -34000 | C26: =B26/$B$7 -> -4.9425789
A27: Net revenue | B27: ='Rev & Unit-by-Unit'!$M$78 -> 13075915 | C27: =B27/$B$7 -> 1900.8453
A29: PROJECT COSTS
B30: Amount | C30: $ / sellable sf | D30: % of cost | E30: Notes
A31: Land | B31: ='Soft Costs'!$C$7 -> 4000000 | C31: =B31/$B$7 -> 581.47987 | D31: =B31/$B$40 -> 0.30537787
A32: Inclusionary Housing certificates (none) | B32: ='Soft Costs'!$G$24 -> 0 | C32: =B32/$B$7 -> 0 | D32: =B32/$B$40 -> 0 | E32: Not needed: the affordable floor area is the on-site unit.
A33: Hard costs | B33: ='Hard Costs'!$G$121 -> 6533100 | C33: =B33/$B$7 -> 949.71653 | D33: =B33/$B$40 -> 0.49876604 | E33: Owner's $450 per gsf above grade; the line items at 725 Grand rates come to about $471/gsf (Hard Costs sheet).
A34: Soft costs, construction period | B34: ='Soft Costs'!$G$49 -> 1549116.8 | C34: =B34/$B$7 -> 225.19506 | D34: =B34/$B$40 -> 0.1182665 | E34: Before the mortgage recording tax; line by line on the Soft Costs sheet.
A35: Mortgage recording tax on the construction loan | B35: ='Soft Costs'!$G$51 -> 260492.59 | C35: =B35/$B$7 -> 37.8678 | D35: =B35/$B$40 -> 0.019887168
A36: Loan origination fee | B36: =Finance!$B$39 -> 93033.069 | C36: =B36/$B$7 -> 13.524214 | D36: =B36/$B$40 -> 0.0071025602
A37: Construction loan interest | B37: =Finance!$B$47 -> 600118.08 | C37: =B37/$B$7 -> 87.239146 | D37: =B37/$B$40 -> 0.045815696 | E37: From the monthly cash flow on the Finance sheet.
A38: Equity placement fee | B38: =Finance!$B$42 -> 0 | C38: =B38/$B$7 -> 0 | D38: =B38/$B$40 -> 0
A39: Sponsor wind-down | B39: ='Soft Costs'!$G$59 -> 62665.5 | C39: =B39/$B$7 -> 9.1096816 | D39: =B39/$B$40 -> 0.0047841642 | E39: Board turnover, warranty reserve, final audit and dissolution, on the Soft Costs sheet.
A40: Total project cost | B40: =SUM(B31:B39) -> 13098526 | C40: =B40/$B$7 -> 1904.1323 | D40: =B40/$B$40 -> 1
A42: PROFIT
A43: Profit | B43: =B27-B40 -> -22611.515 | C43: =B43/$B$7 -> -3.2870352
A44: Margin on cost | B44: =B43/B40 -> -0.0017262641 | E44: Profit ÷ total project cost.
...

Sheet Rev & Unit-by-Unit
A1: 246 South 2nd Street · Revenue and Unit-by-Unit
A2: Base (8 stories at 85 ft, 9 units). All sales revenue lives here: each unit's area and price, the commercial condo value, and the sale costs that take gross revenue down to net revenue. Finance and Master read from this sheet.
A3: Blue = input. Green = linked from Hard Costs. Black = formula. Yellow = the sellable-area adjustment, which affects revenue only.
A5: PRICING
A6: Price, standard units | G6: 1450 | H6: $ / sf | I6: Placeholder at 725 Grand's base case, $1,450/sf, until the Southside comps are pulled. The OM compares an upside at $1,650/sf.
A7: Mezzanine duplex premium (not used) | G7: 0.2 | H7: over standard | I7: No duplex or mezzanine units in this design.
A8: Price, mezzanine duplexes | G8: =$G$6*(1+$G$7) -> 1740 | H8: $ / sf
A10: SELLABLE-AREA ADJUSTMENT (revenue only)
A11: Design sellable sf, from the Hard Costs unit mix | G11: ='Hard Costs'!$C$10 -> 6879 | H11: sf | I11: The real area the costs, zoning check and 3D model use.
A12: Target sellable sf for revenue | G12: 0 | H12: sf | I12: Off (0): revenue uses the designed area. Enter a target to show an upside stretch.
A13: Adjustment | G13: =IF($G$12>0,$G$12-$G$11,0) -> 0 | H13: sf | I13: Spread pro rata across the units below. Does not change construction costs.
A14: Adjustment as a share of design area | G14: =$G$13/$G$11 -> 0
A16: UNIT-BY-UNIT
A17: Unit | B17: Floor(s) | C17: Type (from the unit mix) | D17: Bed-rooms | E17: Baths | F17: Mezza-nine | G17: Design sf (model) | H17: Adjust-ment sf | I17: Sellable sf | J17: Base $ / sf | K17: Unit premium / discount | L17: Asking price override ($) | M17: Unit price ($) | N17: Final $ / sf | O17: Closes, months after TCO | P17: Notes
A18: 4F | B18: 4 | C18: ='Hard Costs'!$B$29 -> Affordable 1-bedroom, floor 4 (4F), for sale | D18: 1 | E18: ='Hard Costs'!$G$29 -> 1 | F18: =IF('Hard Costs'!$H$29=1,"Yes","No") -> No | G18: 858 | H18: =G18*$G$14 -> 0 | I18: =G18+H18 -> 858 | J18: =IF('Hard Costs'!$H$29=1,$G$8,$G$6) -> 1450 | K18: 0 | L18: 300000 | M18: =IF(N(L18)>0,L18,I18*J18*(1+K18)) -> 300000 | N18: =M18/I18 -> 349.65035 | O18: 1 | P18: Affordable homeownership unit, priced at the affordable sale price, not market comps. Closes at TCO.
A19: 4R | B19: 4 | C19: ='Hard Costs'!$B$30 -> 1-bedroom, rear, floors 4-7 (4R, 5R, 6R, 7R) | D19: 1 | E19: ='Hard Costs'!$G$30 -> 1 | F19: =IF('Hard Costs'!$H$30=1,"Yes","No") -> No | G19: 714 | H19: =G19*$G$14 -> 0 | I19: =G19+H19 -> 714 | J19: =IF('Hard Costs'!$H$30=1,$G$8,$G$6) -> 1450 | K19: 0 | M19: =IF(N(L19)>0,L19,I19*J19*(1+K19)) -> 1035300 | N19: =M19/I19 -> 1450 | O19: 1 | P19: Rear, with an 81 sf balcony. Presold off the plans; closes at TCO.
A20: 5F | B20: 5 | C20: ='Hard Costs'!$B$31 -> 2-bedroom, street, floors 5-6 (5F, 6F) | D20: 2 | E20: ='Hard Costs'!$G$31 -> 2 | F20: =IF('Hard Costs'!$H$31=1,"Yes","No") -> No | G20: 858 | H20: =G20*$G$14 -> 0 | I20: =G20+H20 -> 858 | J20: =IF('Hard Costs'!$H$31=1,$G$8,$G$6) -> 1450 | K20: 0 | M20: =IF(N(L20)>0,L20,I20*J20*(1+K20)) -> 1244100 | N20: =M20/I20 -> 1450 | O20: 1 | P20: Street side. Presold off the plans; closes at TCO.
A21: 5R | B21: 5 | C21: ='Hard Costs'!$B$30 -> 1-bedroom, rear, floors 4-7 (4R, 5R, 6R, 7R) | D21: 1 | E21: ='Hard Costs'!$G$30 -> 1 | F21: =IF('Hard Costs'!$H$30=1,"Yes","No") -> No | G21: 719 | H21: =G21*$G$14 -> 0 | I21: =G21+H21 -> 719 | J21: =IF('Hard Costs'!$H$30=1,$G$8,$G$6) -> 1450 | K21: 0 | M21: =IF(N(L21)>0,L21,I21*J21*(1+K21)) -> 1042550 | N21: =M21/I21 -> 1450 | O21: 1 | P21: Rear, with an 85 sf balcony. Presold off the plans; closes at TCO.
A22: 6F | B22: 6 | C22: ='Hard Costs'!$B$31 -> 2-bedroom, street, floors 5-6 (5F, 6F) | D22: 2 | E22: ='Hard Costs'!$G$31 -> 2 | F22: =IF('Hard Costs'!$H$31=1,"Yes","No") -> No | G22: 858 | H22: =G22*$G$14 -> 0 | I22: =G22+H22 -> 858 | J22: =IF('Hard Costs'!$H$31=1,$G$8,$G$6) -> 1450 | K22: 0 | M22: =IF(N(L22)>0,L22,I22*J22*(1+K22)) -> 1244100 | N22: =M22/I22 -> 1450 | O22: 1 | P22: Street side. Presold off the plans; closes at TCO.
A23: 6R | B23: 6 | C23: ='Hard Costs'!$B$30 -> 1-bedroom, rear, floors 4-7 (4R, 5R, 6R, 7R) | D23: 1 | E23: ='Hard Costs'!$G$30 -> 1 | F23: =IF('Hard Costs'!$H$30=1,"Yes","No") -> No | G23: 719 | H23: =G23*$G$14 -> 0 | I23: =G23+H23 -> 719 | J23: =IF('Hard Costs'!$H$30=1,$G$8,$G$6) -> 1450 | K23: 0 | M23: =IF(N(L23)>0,L23,I23*J23*(1+K23)) -> 1042550 | N23: =M23/I23 -> 1450 | O23: 1 | P23: Rear, with a 55 sf balcony. Presold off the plans; closes at TCO.
A24: 7F | B24: 7 | C24: ='Hard Costs'!$B$32 -> Studio with street terrace, floor 7 (7F) | D24: 0 | E24: ='Hard Costs'!$G$32 -> 1 | F24: =IF('Hard Costs'!$H$32=1,"Yes","No") -> No | G24: 567 | H24: =G24*$G$14 -> 0 | I24: =G24+H24 -> 567 | J24: =IF('Hard Costs'!$H$32=1,$G$8,$G$6) -> 1450 | K24: 0 | M24: =IF(N(L24)>0,L24,I24*J24*(1+K24)) -> 822150 | N24: =M24/I24 -> 1450 | O24: 1 | P24: Studio with a 292 sf street terrace on the setback. Presold off the plans; closes at TCO.
A25: 7R | B25: 7 | C25: ='Hard Costs'!$B$30 -> 1-bedroom, rear, floors 4-7 (4R, 5R, 6R, 7R) | D25: 1 | E25: ='Hard Costs'!$G$30 -> 1 | F25: =IF('Hard Costs'!$H$30=1,"Yes","No") -> No | G25: 723 | H25: =G25*$G$14 -> 0 | I25: =G25+H25 -> 723 | J25: =IF('Hard Costs'!$H$30=1,$G$8,$G$6) -> 1450 | K25: 0 | M25: =IF(N(L25)>0,L25,I25*J25*(1+K25)) -> 1048350 | N25: =M25/I25 -> 1450 | O25: 1 | P25: Rear, with a 52 sf balcony. Presold off the plans; closes at TCO.
A26: PH | B26: 8 | C26: ='Hard Costs'!$B$33 -> Full-floor penthouse, floor 8, 2 bedrooms + private roof | D26: 2 | E26: ='Hard Costs'!$G$33 -> 2 | F26: =IF('Hard Costs'!$H$33=1,"Yes","No") -> No | G26: 863 | H26: =G26*$G$14 -> 0 | I26: =G26+H26 -> 863 | J26: =IF('Hard Costs'!$H$33=1,$G$8,$G$6) -> 1450 | K26: 0 | M26: =IF(N(L26)>0,L26,I26*J26*(1+K26)) -> 1251350 | N26: =M26/I26 -> 1450 | O26: 1 | P26: Full-floor penthouse: setback terrace and balcony (431 sf) plus a 1,505 sf private roof. Presold off the plans; closes at TCO.
A27: Total | D27: =SUM(D18:D26) -> 11 | E27: =SUM(E18:E26) -> 12 | G27: =SUM(G18:G26) -> 6879 | H27: =SUM(H18:H26) -> 0 | I27: =SUM(I18:I26) -> 6879 | M27: =SUM(M18:M26) -> 9030450 | N27: =M27/I27 -> 1312.7562 | O27: =MAX(O18:O26) -> 1
A28: Check against the Hard Costs unit mix | G28: =IF(AND(COUNT(G18:G26)='Hard Costs'!$C$12,ABS(G27-$G$11)<1),"OK","UNIT MIX CHANGED: update this list") -> OK | I28: If you change the unit mix on Hard Costs, add or remove rows here to match. Design sf per unit is typed in from the model.
A29: Revenue from the sellable-area adjustment | M29: =IF(N(L18)>0,0,H18*J18*(1+K18))+IF(N(L19)>0,0,H19*J19*(1+K19))+IF(N(L20)>0,0,H20*J20*(1+K20))+IF(N(L21)>0,0,H21*J21*(1+K21))+IF(N(L22)>0,0,H22*J22*(1+K22))+IF(N(L23)>0,0,H23*J23*(1+K23))+IF(N(L24)>0,0,H24*J24*(1+K24))+IF(N(L25)>0,0,H25*J25*(1+K25))+IF(N(L26)>0,0,H26*J26*(1+K26)) -> 0 | P29: Gross condo sales that come only from the adjustment (units with an asking-price override excluded).
A31: COMMERCIAL CONDO
A32: Commercial at grade (1st floor), sf | G32: ='Hard Costs'!$C$9 -> 1717 | H32: sf | I32: Sellable, from the model; set on Hard Costs.
A33: Rent, at grade | G33: 65 | H33: $ / sf / yr | I33: Placeholder for a mid-block Southside storefront (725 Grand used $90 for a Grand and Graham corner). Confirm with a broker.
A34: Commercial, 2nd floor, sf | G34: ='Hard Costs'!$C$22 -> 2616 | H34: sf | I34: Full 2nd floor: office, medical or community use. Set on Hard Costs.
A35: Rent, 2nd floor | G35: 40 | H35: $ / sf / yr | I35: Placeholder for second-floor space. Confirm with a broker.
A36: Vacancy | G36: 0 | I36: 0% as in the 725 Grand base case (pre-leased). The 5% value below is what a lender might use.
A37: Landlord expenses | G37: 0.03 | H37: of rent
A38: Cellar commercial and community facility area | G38: ='Hard Costs'!$C$17 -> 1857 | H38: sf | I38: Below-grade space sold with the commercial condo. Set on Hard Costs.
A39: Cellar rent | G39: 25 | H39: $ / sf / yr | I39: Below-grade space rents for a fraction of the ground floor.
A40: Net operating income | G40: =($G$32*$G$33+$G$34*$G$35+$G$38*$G$39)*(1-$G$36-$G$37) -> 254789.9 | H40: $ / yr | I40: Ground floor, 2nd floor and cellar, less vacancy and landlord expenses.
A41: Cap rate | G41: 0.05
A42: Commercial condo sale value | G42: =$G$40/$G$41 -> 5095798 | H42: $
A43: Value at 5% vacancy, for comparison | G43: =($G$32*$G$33+$G$34*$G$35+$G$38*$G$39)*(1-0.05-$G$37)/$G$41 -> 4833128 | H43: $ | I43: What a lender or appraiser might use instead.
A45: GROSS REVENUE
...

Sheet Finance
A1: 246 South 2nd Street · Finance
A2: 246 South 2nd Street on its own 3,100 sf lot in R6 with a commercial overlay: 8 stories at 85 ft (13'-11" ground floor, 11 ft 2nd floor, 10 ft above), plus a cellar and a private roof. 9 condos (8 market-rate and one affordable homeownership unit), 6,879 sellable sf; commercial on the 1st and 2nd floors (4,333 sf sellable) plus 1,857 sf in the cellar; Zone Green (ULEB) 5% exclusion; no air rights or certificates; all-electric.
A3: Blue = input you can change. Green = linked from the Hard Costs, Soft Costs and Rev & Unit-by-Unit sheets. Black = formula. The schedule months are placeholders until we set the timing together; the Gantt chart will use them.
A5: SCHEDULE (placeholder months)
A6: Pre-development: design, approvals and permits | B6: 6 | C6: months | D6: From land closing (month 0) to the start of construction. Equity carries these months.
A7: Construction: ground-breaking to TCO | B7: 20 | C7: months | D7: 20 months, as in the 725 Grand base case. Hard-cost draws come from the Gantt sheet.
A8: Sell-out after completion | B8: 6 | C8: months | D8: Window for closings after TCO. Each unit closes in the month set on the Rev & Unit-by-Unit sheet: presold units at TCO, the staged duplexes a few months later.
A9: Retail sale closes, months after completion | B9: 1 | C9: months
A10: Project length | B10: =$B$6+$B$7+$B$8 -> 32 | C10: months | D10: The Soft Costs sheet's project length links here. The monthly grid below runs 48 months.
A12: CONSTRUCTION LOAN
A13: Loan-to-cost | B13: 0.7 | D13: Share of costs before financing that the loan funds. Equity goes in first.
A14: Interest rate | B14: 0.095 | C14: per year | D14: Owner, Oct 16 2026: 9.5%. Accrues monthly on the drawn balance and is added to the loan.
A15: Origination fee | B15: 0.01 | C15: of commitment | D15: Paid when the loan closes, in the first month of construction.
A16: Interest reserve allowance | B16: 0.1 | C16: of loan | D16: Added to the loan commitment to cover capitalized interest. Sizes the commitment, the origination fee and the mortgage recording tax.
A18: EQUITY
A19: Preferred return to investors | B19: 0.08 | C19: per year | D19: Compounded monthly on invested capital until it is returned. The deck uses 8%; your Base w Fin tab charged 12% on land equity.
A20: Sponsor promote above the pref | B20: 0.3 | C20: of cash above pref | D20: After capital plus pref is paid back, the sponsor takes this share and investors the rest (the deck's 70/30).
A21: Sponsor co-investment | B21: 0.1 | C21: of equity | D21: Sponsor's own money in the deal, on the same terms as investors.
A22: Equity placement fee | B22: 0 | C22: of equity | D22: Fee to a broker for raising the equity, paid at closing. 0% unless you use a placement agent.
A24: FROM THE COST SHEETS
A25: Land purchase price | B25: ='Soft Costs'!$C$7 -> 4000000 | C25: $ | D25: Paid at closing, month 0.
A26: Inclusionary Housing certificates (none) | B26: ='Soft Costs'!$G$24 -> 0 | C26: $ | D26: Not needed for this design.
A27: Total hard cost | B27: ='Hard Costs'!$G$121 -> 6533100 | C27: $
A28: Construction soft costs, before mortgage recording tax | B28: ='Soft Costs'!$G$49 -> 1549116.8 | C28: $ | D28: Spread evenly from closing to the end of construction.
A29: Mortgage recording tax on the construction loan | B29: ='Soft Costs'!$G$51 -> 260492.59 | C29: $ | D29: Paid when the loan closes.
A30: Condo gross sales | B30: ='Rev & Unit-by-Unit'!$M$27 -> 9030450 | C30: $
A31: Condo sale costs | B31: ='Rev & Unit-by-Unit'!$M$61 -> 518219.21 | C31: $ | D31: Commissions, transfer taxes and closing costs, paid as units close.
A32: Retail condo sale value | B32: ='Rev & Unit-by-Unit'!$G$42 -> 5095798 | C32: $
A33: Retail sale costs | B33: ='Rev & Unit-by-Unit'!$M$68 -> 498114.25 | C33: $
A34: End-loan packages and sponsor wind-down | B34: ='Rev & Unit-by-Unit'!$M$74+'Soft Costs'!$G$59 -> 96665.5 | C34: $ | D34: Paid in the last month.
A36: LOAN AND EQUITY SIZING
A37: Costs before financing, excluding recording tax | B37: =$B$25+$B$26+$B$27+$B$28 -> 12082217 | C37: $ | D37: Land + hard + construction soft costs.
A38: Loan commitment | B38: =$B$13*$B$37*(1+$B$16) -> 9303306.9 | C38: $ | D38: Loan-to-cost × costs, plus the interest reserve allowance. The Soft Costs sheet's recording tax is figured on this.
A39: Loan origination fee | B39: =$B$15*$B$38 -> 93033.069 | C39: $
A40: Costs before the loan closes | B40: =$B$25+$B$26+$B$28*($B$6+1)/($B$6+$B$7+1) -> 4401622.9 | C40: $ | D40: Land and pre-development soft costs. Equity must cover at least this.
A41: Equity required | B41: =MAX((1-$B$13)*($B$37+$B$29),$B$40) -> 4401622.9 | C41: $ | D41: (1 - loan-to-cost) x costs including recording tax, or the costs before the loan closes if that is more.
A42: Equity placement fee | B42: =$B$22*$B$41 -> 0 | C42: $
A43: Total equity | B43: =$B$41+$B$42 -> 4401622.9 | C43: $ | D43: Invested first, before any loan draws.
A45: RESULTS
A46: Total project cost, including financing | B46: =B78+B82 -> 13035861 | C46: $
...

Sheet Gantt
A1: 246 South 2nd Street · Gantt and Construction Draw Schedule
A2: Base (8 stories at 85 ft, 20-month build). Month by month from the equity raise to the last closing. Each hard-cost line is spread evenly between its start and end month; the owner-budget adjustment and contingency are spread pro rata.
A3: Blue = start and end months you can change. Green = linked. Shaded cells show when each activity happens; construction cells show the monthly draw in $ thousands.
A5: SCHEDULE
A6: Land closing (month 0) | B6: 46478 | F6: Placeholder carried from 725 Grand: 3 months to find investors, 3 months to close.
A7: Pre-development | B7: =Finance!$B$6 -> 6 | C7: months | F7: Set on the Finance sheet.
A8: Construction | B8: =Finance!$B$7 -> 20 | C8: months | F8: Set on the Finance sheet. Construction month 1 = project month pre-development + 1.
A9: Sell-out after TCO | B9: =Finance!$B$8 -> 6 | C9: months
A10: Offering plan accepted by the Attorney General | B10: 12 | C10: proj. month | F10: Presales start here. Contracts cannot be signed before acceptance.
A12: Project month | F12: -6 | G12: -5 | H12: -4 | I12: -3 | J12: -2 | K12: -1 | L12: 0 | M12: 1 | N12: 2 | O12: 3 | P12: 4 | Q12: 5 | R12: 6 | S12: 7 | T12: 8 | U12: 9 | V12: 10 | W12: 11 | X12: 12 | Y12: 13 | Z12: 14 | AA12: 15 | AB12: 16 | AC12: 17 | AD12: 18 | AE12: 19 | AF12: 20 | AG12: 21 | AH12: 22 | AI12: 23 | AJ12: 24 | AK12: 25 | AL12: 26 | AM12: 27 | AN12: 28 | AO12: 29 | AP12: 30 | AQ12: 31 | AR12: 32 | AS12: 33 | AT12: 34 | AU12: 35 | AV12: 36 | AW12: 37 | AX12: 38 | AY12: 39 | AZ12: 40 | BA12: 41 | BB12: 42 | BC12: 43 | BD12: 44 | BE12: 45 | BF12: 46 | BG12: 47
A13: Month | B13: Budget | C13: Start | D13: End | F13: =DATE(YEAR($B$6),MONTH($B$6)+F$12,1) -> 46296 | G13: =DATE(YEAR($B$6),MONTH($B$6)+G$12,1) -> 46327 | H13: =DATE(YEAR($B$6),MONTH($B$6)+H$12,1) -> 46357 | I13: =DATE(YEAR($B$6),MONTH($B$6)+I$12,1) -> 46388 | J13: =DATE(YEAR($B$6),MONTH($B$6)+J$12,1) -> 46419 | K13: =DATE(YEAR($B$6),MONTH($B$6)+K$12,1) -> 46447 | L13: =DATE(YEAR($B$6),MONTH($B$6)+L$12,1) -> 46478 | M13: =DATE(YEAR($B$6),MONTH($B$6)+M$12,1) -> 46508 | ... BG13: =DATE(YEAR($B$6),MONTH($B$6)+BG$12,1) -> 47908
A14: Phase | F14: =IF(F$12<0,"Raise",IF(F$12=0,"Close",IF(F$12<=$B$7,"Pre-dev",IF(F$12<=$B$7+$B$8,"Build",IF(F$12<=$B$7+$B$8+$B$9,"Sell",""))))) -> Raise | G14: =IF(G$12<0,"Raise",IF(G$12=0,"Close",IF(G$12<=$B$7,"Pre-dev",IF(G$12<=$B$7+$B$8,"Build",IF(G$12<=$B$7+$B$8+$B$9,"Sell",""))))) -> Raise | H14: =IF(H$12<0,"Raise",IF(H$12=0,"Close",IF(H$12<=$B$7,"Pre-dev",IF(H$12<=$B$7+$B$8,"Build",IF(H$12<=$B$7+$B$8+$B$9,"Sell",""))))) -> Raise | I14: =IF(I$12<0,"Raise",IF(I$12=0,"Close",IF(I$12<=$B$7,"Pre-dev",IF(I$12<=$B$7+$B$8,"Build",IF(I$12<=$B$7+$B$8+$B$9,"Sell",""))))) -> Raise | J14: =IF(J$12<0,"Raise",IF(J$12=0,"Close",IF(J$12<=$B$7,"Pre-dev",IF(J$12<=$B$7+$B$8,"Build",IF(J$12<=$B$7+$B$8+$B$9,"Sell",""))))) -> Raise | K14: =IF(K$12<0,"Raise",IF(K$12=0,"Close",IF(K$12<=$B$7,"Pre-dev",IF(K$12<=$B$7+$B$8,"Build",IF(K$12<=$B$7+$B$8+$B$9,"Sell",""))))) -> Raise | L14: =IF(L$12<0,"Raise",IF(L$12=0,"Close",IF(L$12<=$B$7,"Pre-dev",IF(L$12<=$B$7+$B$8,"Build",IF(L$12<=$B$7+$B$8+$B$9,"Sell",""))))) -> Close | M14: =IF(M$12<0,"Raise",IF(M$12=0,"Close",IF(M$12<=$B$7,"Pre-dev",IF(M$12<=$B$7+$B$8,"Build",IF(M$12<=$B$7+$B$8+$B$9,"Sell",""))))) -> Pre-dev | ... BG14: =IF(BG$12<0,"Raise",IF(BG$12=0,"Close",IF(BG$12<=$B$7,"Pre-dev",IF(BG$12<=$B$7+$B$8,"Build",IF(BG$12<=$B$7+$B$8+$B$9,"Sell","")))))
A16: BEFORE CONSTRUCTION | F16: Start and end are project months (0 = land closing).
A17: Equity raise: find investors | C17: -6 | D17: -4 | F17: =IF(AND(F$12>=$C17,F$12<=$D17),1,0) -> 1 | G17: =IF(AND(G$12>=$C17,G$12<=$D17),1,0) -> 1 | H17: =IF(AND(H$12>=$C17,H$12<=$D17),1,0) -> 1 | I17: =IF(AND(I$12>=$C17,I$12<=$D17),1,0) -> 0 | J17: =IF(AND(J$12>=$C17,J$12<=$D17),1,0) -> 0 | K17: =IF(AND(K$12>=$C17,K$12<=$D17),1,0) -> 0 | L17: =IF(AND(L$12>=$C17,L$12<=$D17),1,0) -> 0 | M17: =IF(AND(M$12>=$C17,M$12<=$D17),1,0) -> 0 | ... BG17: =IF(AND(BG$12>=$C17,BG$12<=$D17),1,0) -> 0
A18: Closing period | C18: -3 | D18: -1 | F18: =IF(AND(F$12>=$C18,F$12<=$D18),1,0) -> 0 | G18: =IF(AND(G$12>=$C18,G$12<=$D18),1,0) -> 0 | H18: =IF(AND(H$12>=$C18,H$12<=$D18),1,0) -> 0 | I18: =IF(AND(I$12>=$C18,I$12<=$D18),1,0) -> 1 | J18: =IF(AND(J$12>=$C18,J$12<=$D18),1,0) -> 1 | K18: =IF(AND(K$12>=$C18,K$12<=$D18),1,0) -> 1 | L18: =IF(AND(L$12>=$C18,L$12<=$D18),1,0) -> 0 | M18: =IF(AND(M$12>=$C18,M$12<=$D18),1,0) -> 0 | ... BG18: =IF(AND(BG$12>=$C18,BG$12<=$D18),1,0) -> 0
A19: Land closing | C19: 0 | D19: 0 | F19: =IF(AND(F$12>=$C19,F$12<=$D19),1,0) -> 0 | G19: =IF(AND(G$12>=$C19,G$12<=$D19),1,0) -> 0 | H19: =IF(AND(H$12>=$C19,H$12<=$D19),1,0) -> 0 | I19: =IF(AND(I$12>=$C19,I$12<=$D19),1,0) -> 0 | J19: =IF(AND(J$12>=$C19,J$12<=$D19),1,0) -> 0 | K19: =IF(AND(K$12>=$C19,K$12<=$D19),1,0) -> 0 | L19: =IF(AND(L$12>=$C19,L$12<=$D19),1,0) -> 1 | M19: =IF(AND(M$12>=$C19,M$12<=$D19),1,0) -> 0 | ... BG19: =IF(AND(BG$12>=$C19,BG$12<=$D19),1,0) -> 0
A20: Design and Buildings Department filing | C20: 1 | D20: 3 | F20: =IF(AND(F$12>=$C20,F$12<=$D20),1,0) -> 0 | G20: =IF(AND(G$12>=$C20,G$12<=$D20),1,0) -> 0 | H20: =IF(AND(H$12>=$C20,H$12<=$D20),1,0) -> 0 | I20: =IF(AND(I$12>=$C20,I$12<=$D20),1,0) -> 0 | J20: =IF(AND(J$12>=$C20,J$12<=$D20),1,0) -> 0 | K20: =IF(AND(K$12>=$C20,K$12<=$D20),1,0) -> 0 | L20: =IF(AND(L$12>=$C20,L$12<=$D20),1,0) -> 0 | M20: =IF(AND(M$12>=$C20,M$12<=$D20),1,0) -> 1 | ... BG20: =IF(AND(BG$12>=$C20,BG$12<=$D20),1,0) -> 0
A21: Phase I environmental | C21: 1 | D21: 4 | F21: =IF(AND(F$12>=$C21,F$12<=$D21),1,0) -> 0 | G21: =IF(AND(G$12>=$C21,G$12<=$D21),1,0) -> 0 | H21: =IF(AND(H$12>=$C21,H$12<=$D21),1,0) -> 0 | I21: =IF(AND(I$12>=$C21,I$12<=$D21),1,0) -> 0 | J21: =IF(AND(J$12>=$C21,J$12<=$D21),1,0) -> 0 | K21: =IF(AND(K$12>=$C21,K$12<=$D21),1,0) -> 0 | L21: =IF(AND(L$12>=$C21,L$12<=$D21),1,0) -> 0 | M21: =IF(AND(M$12>=$C21,M$12<=$D21),1,0) -> 1 | ... BG21: =IF(AND(BG$12>=$C21,BG$12<=$D21),1,0) -> 0
A22: ULEB energy model and Zone Green filing | C22: 2 | D22: 4 | F22: =IF(AND(F$12>=$C22,F$12<=$D22),1,0) -> 0 | G22: =IF(AND(G$12>=$C22,G$12<=$D22),1,0) -> 0 | H22: =IF(AND(H$12>=$C22,H$12<=$D22),1,0) -> 0 | I22: =IF(AND(I$12>=$C22,I$12<=$D22),1,0) -> 0 | J22: =IF(AND(J$12>=$C22,J$12<=$D22),1,0) -> 0 | K22: =IF(AND(K$12>=$C22,K$12<=$D22),1,0) -> 0 | L22: =IF(AND(L$12>=$C22,L$12<=$D22),1,0) -> 0 | M22: =IF(AND(M$12>=$C22,M$12<=$D22),1,0) -> 0 | ... BG22: =IF(AND(BG$12>=$C22,BG$12<=$D22),1,0) -> 0
A23: Offering plan drafted and submitted to the AG | C23: 3 | D23: 6 | F23: =IF(AND(F$12>=$C23,F$12<=$D23),1,0) -> 0 | G23: =IF(AND(G$12>=$C23,G$12<=$D23),1,0) -> 0 | H23: =IF(AND(H$12>=$C23,H$12<=$D23),1,0) -> 0 | I23: =IF(AND(I$12>=$C23,I$12<=$D23),1,0) -> 0 | J23: =IF(AND(J$12>=$C23,J$12<=$D23),1,0) -> 0 | K23: =IF(AND(K$12>=$C23,K$12<=$D23),1,0) -> 0 | L23: =IF(AND(L$12>=$C23,L$12<=$D23),1,0) -> 0 | M23: =IF(AND(M$12>=$C23,M$12<=$D23),1,0) -> 0 | ... BG23: =IF(AND(BG$12>=$C23,BG$12<=$D23),1,0) -> 0
A24: Buildings Department approvals and permits | C24: 4 | D24: 6 | F24: =IF(AND(F$12>=$C24,F$12<=$D24),1,0) -> 0 | G24: =IF(AND(G$12>=$C24,G$12<=$D24),1,0) -> 0 | H24: =IF(AND(H$12>=$C24,H$12<=$D24),1,0) -> 0 | I24: =IF(AND(I$12>=$C24,I$12<=$D24),1,0) -> 0 | J24: =IF(AND(J$12>=$C24,J$12<=$D24),1,0) -> 0 | K24: =IF(AND(K$12>=$C24,K$12<=$D24),1,0) -> 0 | L24: =IF(AND(L$12>=$C24,L$12<=$D24),1,0) -> 0 | M24: =IF(AND(M$12>=$C24,M$12<=$D24),1,0) -> 0 | ... BG24: =IF(AND(BG$12>=$C24,BG$12<=$D24),1,0) -> 0
A25: GC bidding and buyout | C25: 4 | D25: 6 | F25: =IF(AND(F$12>=$C25,F$12<=$D25),1,0) -> 0 | G25: =IF(AND(G$12>=$C25,G$12<=$D25),1,0) -> 0 | H25: =IF(AND(H$12>=$C25,H$12<=$D25),1,0) -> 0 | I25: =IF(AND(I$12>=$C25,I$12<=$D25),1,0) -> 0 | J25: =IF(AND(J$12>=$C25,J$12<=$D25),1,0) -> 0 | K25: =IF(AND(K$12>=$C25,K$12<=$D25),1,0) -> 0 | L25: =IF(AND(L$12>=$C25,L$12<=$D25),1,0) -> 0 | M25: =IF(AND(M$12>=$C25,M$12<=$D25),1,0) -> 0 | ... BG25: =IF(AND(BG$12>=$C25,BG$12<=$D25),1,0) -> 0
A26: Construction loan closing | C26: 6 | D26: 6 | F26: =IF(AND(F$12>=$C26,F$12<=$D26),1,0) -> 0 | G26: =IF(AND(G$12>=$C26,G$12<=$D26),1,0) -> 0 | H26: =IF(AND(H$12>=$C26,H$12<=$D26),1,0) -> 0 | I26: =IF(AND(I$12>=$C26,I$12<=$D26),1,0) -> 0 | J26: =IF(AND(J$12>=$C26,J$12<=$D26),1,0) -> 0 | K26: =IF(AND(K$12>=$C26,K$12<=$D26),1,0) -> 0 | L26: =IF(AND(L$12>=$C26,L$12<=$D26),1,0) -> 0 | M26: =IF(AND(M$12>=$C26,M$12<=$D26),1,0) -> 0 | ... BG26: =IF(AND(BG$12>=$C26,BG$12<=$D26),1,0) -> 0
A28: CONSTRUCTION DRAWS | F28: Start and end are construction months (1 = first month of construction). Cells show $ thousands drawn that month.
A29: Substructure and shell
A30: Excavation and soil removal | B30: ='Hard Costs'!$G$62 -> 61200 | C30: 2 | D30: 4 | F30: =IF(AND(F$12-$B$7>=$C30,F$12-$B$7<=$D30),$B30/($D30-$C30+1),0) -> 0 | G30: =IF(AND(G$12-$B$7>=$C30,G$12-$B$7<=$D30),$B30/($D30-$C30+1),0) -> 0 | H30: =IF(AND(H$12-$B$7>=$C30,H$12-$B$7<=$D30),$B30/($D30-$C30+1),0) -> 0 | I30: =IF(AND(I$12-$B$7>=$C30,I$12-$B$7<=$D30),$B30/($D30-$C30+1),0) -> 0 | J30: =IF(AND(J$12-$B$7>=$C30,J$12-$B$7<=$D30),$B30/($D30-$C30+1),0) -> 0 | K30: =IF(AND(K$12-$B$7>=$C30,K$12-$B$7<=$D30),$B30/($D30-$C30+1),0) -> 0 | L30: =IF(AND(L$12-$B$7>=$C30,L$12-$B$7<=$D30),$B30/($D30-$C30+1),0) -> 0 | M30: =IF(AND(M$12-$B$7>=$C30,M$12-$B$7<=$D30),$B30/($D30-$C30+1),0) -> 0 | ... BG30: =IF(AND(BG$12-$B$7>=$C30,BG$12-$B$7<=$D30),$B30/($D30-$C30+1),0) -> 0
A31: Dewatering and support of excavation | B31: ='Hard Costs'!$G$63 -> 70000 | C31: 2 | D31: 4 | F31: =IF(AND(F$12-$B$7>=$C31,F$12-$B$7<=$D31),$B31/($D31-$C31+1),0) -> 0 | G31: =IF(AND(G$12-$B$7>=$C31,G$12-$B$7<=$D31),$B31/($D31-$C31+1),0) -> 0 | H31: =IF(AND(H$12-$B$7>=$C31,H$12-$B$7<=$D31),$B31/($D31-$C31+1),0) -> 0 | I31: =IF(AND(I$12-$B$7>=$C31,I$12-$B$7<=$D31),$B31/($D31-$C31+1),0) -> 0 | J31: =IF(AND(J$12-$B$7>=$C31,J$12-$B$7<=$D31),$B31/($D31-$C31+1),0) -> 0 | K31: =IF(AND(K$12-$B$7>=$C31,K$12-$B$7<=$D31),$B31/($D31-$C31+1),0) -> 0 | L31: =IF(AND(L$12-$B$7>=$C31,L$12-$B$7<=$D31),$B31/($D31-$C31+1),0) -> 0 | M31: =IF(AND(M$12-$B$7>=$C31,M$12-$B$7<=$D31),$B31/($D31-$C31+1),0) -> 0 | ... BG31: =IF(AND(BG$12-$B$7>=$C31,BG$12-$B$7<=$D31),$B31/($D31-$C31+1),0) -> 0
A32: Underpinning and shoring at shared lot lines | B32: ='Hard Costs'!$G$64 -> 234000 | C32: 2 | D32: 4 | F32: =IF(AND(F$12-$B$7>=$C32,F$12-$B$7<=$D32),$B32/($D32-$C32+1),0) -> 0 | G32: =IF(AND(G$12-$B$7>=$C32,G$12-$B$7<=$D32),$B32/($D32-$C32+1),0) -> 0 | H32: =IF(AND(H$12-$B$7>=$C32,H$12-$B$7<=$D32),$B32/($D32-$C32+1),0) -> 0 | I32: =IF(AND(I$12-$B$7>=$C32,I$12-$B$7<=$D32),$B32/($D32-$C32+1),0) -> 0 | J32: =IF(AND(J$12-$B$7>=$C32,J$12-$B$7<=$D32),$B32/($D32-$C32+1),0) -> 0 | K32: =IF(AND(K$12-$B$7>=$C32,K$12-$B$7<=$D32),$B32/($D32-$C32+1),0) -> 0 | L32: =IF(AND(L$12-$B$7>=$C32,L$12-$B$7<=$D32),$B32/($D32-$C32+1),0) -> 0 | M32: =IF(AND(M$12-$B$7>=$C32,M$12-$B$7<=$D32),$B32/($D32-$C32+1),0) -> 0 | ... BG32: =IF(AND(BG$12-$B$7>=$C32,BG$12-$B$7<=$D32),$B32/($D32-$C32+1),0) -> 0
A33: Footings and foundation walls | B33: ='Hard Costs'!$G$65 -> 101660 | C33: 4 | D33: 6 | F33: =IF(AND(F$12-$B$7>=$C33,F$12-$B$7<=$D33),$B33/($D33-$C33+1),0) -> 0 | G33: =IF(AND(G$12-$B$7>=$C33,G$12-$B$7<=$D33),$B33/($D33-$C33+1),0) -> 0 | H33: =IF(AND(H$12-$B$7>=$C33,H$12-$B$7<=$D33),$B33/($D33-$C33+1),0) -> 0 | I33: =IF(AND(I$12-$B$7>=$C33,I$12-$B$7<=$D33),$B33/($D33-$C33+1),0) -> 0 | J33: =IF(AND(J$12-$B$7>=$C33,J$12-$B$7<=$D33),$B33/($D33-$C33+1),0) -> 0 | K33: =IF(AND(K$12-$B$7>=$C33,K$12-$B$7<=$D33),$B33/($D33-$C33+1),0) -> 0 | L33: =IF(AND(L$12-$B$7>=$C33,L$12-$B$7<=$D33),$B33/($D33-$C33+1),0) -> 0 | M33: =IF(AND(M$12-$B$7>=$C33,M$12-$B$7<=$D33),$B33/($D33-$C33+1),0) -> 0 | ... BG33: =IF(AND(BG$12-$B$7>=$C33,BG$12-$B$7<=$D33),$B33/($D33-$C33+1),0) -> 0
A34: Cellar slab, waterproofing and vapour barrier | B34: ='Hard Costs'!$G$66 -> 55080 | C34: 5 | D34: 6 | F34: =IF(AND(F$12-$B$7>=$C34,F$12-$B$7<=$D34),$B34/($D34-$C34+1),0) -> 0 | G34: =IF(AND(G$12-$B$7>=$C34,G$12-$B$7<=$D34),$B34/($D34-$C34+1),0) -> 0 | H34: =IF(AND(H$12-$B$7>=$C34,H$12-$B$7<=$D34),$B34/($D34-$C34+1),0) -> 0 | I34: =IF(AND(I$12-$B$7>=$C34,I$12-$B$7<=$D34),$B34/($D34-$C34+1),0) -> 0 | J34: =IF(AND(J$12-$B$7>=$C34,J$12-$B$7<=$D34),$B34/($D34-$C34+1),0) -> 0 | K34: =IF(AND(K$12-$B$7>=$C34,K$12-$B$7<=$D34),$B34/($D34-$C34+1),0) -> 0 | L34: =IF(AND(L$12-$B$7>=$C34,L$12-$B$7<=$D34),$B34/($D34-$C34+1),0) -> 0 | M34: =IF(AND(M$12-$B$7>=$C34,M$12-$B$7<=$D34),$B34/($D34-$C34+1),0) -> 0 | ... BG34: =IF(AND(BG$12-$B$7>=$C34,BG$12-$B$7<=$D34),$B34/($D34-$C34+1),0) -> 0
A35: Demolition of the existing building | B35: ='Hard Costs'!$G$67 -> 0 | C35: 1 | D35: 2 | F35: =IF(AND(F$12-$B$7>=$C35,F$12-$B$7<=$D35),$B35/($D35-$C35+1),0) -> 0 | G35: =IF(AND(G$12-$B$7>=$C35,G$12-$B$7<=$D35),$B35/($D35-$C35+1),0) -> 0 | H35: =IF(AND(H$12-$B$7>=$C35,H$12-$B$7<=$D35),$B35/($D35-$C35+1),0) -> 0 | I35: =IF(AND(I$12-$B$7>=$C35,I$12-$B$7<=$D35),$B35/($D35-$C35+1),0) -> 0 | J35: =IF(AND(J$12-$B$7>=$C35,J$12-$B$7<=$D35),$B35/($D35-$C35+1),0) -> 0 | K35: =IF(AND(K$12-$B$7>=$C35,K$12-$B$7<=$D35),$B35/($D35-$C35+1),0) -> 0 | L35: =IF(AND(L$12-$B$7>=$C35,L$12-$B$7<=$D35),$B35/($D35-$C35+1),0) -> 0 | M35: =IF(AND(M$12-$B$7>=$C35,M$12-$B$7<=$D35),$B35/($D35-$C35+1),0) -> 0 | ... BG35: =IF(AND(BG$12-$B$7>=$C35,BG$12-$B$7<=$D35),$B35/($D35-$C35+1),0) -> 0
A36: Superstructure, ground to roof | B36: ='Hard Costs'!$G$68 -> 180829.65 | C36: 6 | D36: 11 | F36: =IF(AND(F$12-$B$7>=$C36,F$12-$B$7<=$D36),$B36/($D36-$C36+1),0) -> 0 | G36: =IF(AND(G$12-$B$7>=$C36,G$12-$B$7<=$D36),$B36/($D36-$C36+1),0) -> 0 | H36: =IF(AND(H$12-$B$7>=$C36,H$12-$B$7<=$D36),$B36/($D36-$C36+1),0) -> 0 | I36: =IF(AND(I$12-$B$7>=$C36,I$12-$B$7<=$D36),$B36/($D36-$C36+1),0) -> 0 | J36: =IF(AND(J$12-$B$7>=$C36,J$12-$B$7<=$D36),$B36/($D36-$C36+1),0) -> 0 | K36: =IF(AND(K$12-$B$7>=$C36,K$12-$B$7<=$D36),$B36/($D36-$C36+1),0) -> 0 | L36: =IF(AND(L$12-$B$7>=$C36,L$12-$B$7<=$D36),$B36/($D36-$C36+1),0) -> 0 | M36: =IF(AND(M$12-$B$7>=$C36,M$12-$B$7<=$D36),$B36/($D36-$C36+1),0) -> 0 | ... BG36: =IF(AND(BG$12-$B$7>=$C36,BG$12-$B$7<=$D36),$B36/($D36-$C36+1),0) -> 0
A37: Super Structure - Floor Slab | B37: ='Hard Costs'!$G$69 -> 435540 | C37: 6 | D37: 11 | F37: =IF(AND(F$12-$B$7>=$C37,F$12-$B$7<=$D37),$B37/($D37-$C37+1),0) -> 0 | G37: =IF(AND(G$12-$B$7>=$C37,G$12-$B$7<=$D37),$B37/($D37-$C37+1),0) -> 0 | H37: =IF(AND(H$12-$B$7>=$C37,H$12-$B$7<=$D37),$B37/($D37-$C37+1),0) -> 0 | I37: =IF(AND(I$12-$B$7>=$C37,I$12-$B$7<=$D37),$B37/($D37-$C37+1),0) -> 0 | J37: =IF(AND(J$12-$B$7>=$C37,J$12-$B$7<=$D37),$B37/($D37-$C37+1),0) -> 0 | K37: =IF(AND(K$12-$B$7>=$C37,K$12-$B$7<=$D37),$B37/($D37-$C37+1),0) -> 0 | L37: =IF(AND(L$12-$B$7>=$C37,L$12-$B$7<=$D37),$B37/($D37-$C37+1),0) -> 0 | M37: =IF(AND(M$12-$B$7>=$C37,M$12-$B$7<=$D37),$B37/($D37-$C37+1),0) -> 0 | ... BG37: =IF(AND(BG$12-$B$7>=$C37,BG$12-$B$7<=$D37),$B37/($D37-$C37+1),0) -> 0
A38: Rooftop MEP penthouse | B38: ='Hard Costs'!$G$70 -> 0 | C38: 11 | D38: 12 | F38: =IF(AND(F$12-$B$7>=$C38,F$12-$B$7<=$D38),$B38/($D38-$C38+1),0) -> 0 | G38: =IF(AND(G$12-$B$7>=$C38,G$12-$B$7<=$D38),$B38/($D38-$C38+1),0) -> 0 | H38: =IF(AND(H$12-$B$7>=$C38,H$12-$B$7<=$D38),$B38/($D38-$C38+1),0) -> 0 | I38: =IF(AND(I$12-$B$7>=$C38,I$12-$B$7<=$D38),$B38/($D38-$C38+1),0) -> 0 | J38: =IF(AND(J$12-$B$7>=$C38,J$12-$B$7<=$D38),$B38/($D38-$C38+1),0) -> 0 | K38: =IF(AND(K$12-$B$7>=$C38,K$12-$B$7<=$D38),$B38/($D38-$C38+1),0) -> 0 | L38: =IF(AND(L$12-$B$7>=$C38,L$12-$B$7<=$D38),$B38/($D38-$C38+1),0) -> 0 | M38: =IF(AND(M$12-$B$7>=$C38,M$12-$B$7<=$D38),$B38/($D38-$C38+1),0) -> 0 | ... BG38: =IF(AND(BG$12-$B$7>=$C38,BG$12-$B$7<=$D38),$B38/($D38-$C38+1),0) -> 0
A39: Envelope
A40: Windows: high-performance double-pane, street walls | B40: ='Hard Costs'!$G$73 -> 176000 | C40: 10 | D40: 15 | F40: =IF(AND(F$12-$B$7>=$C40,F$12-$B$7<=$D40),$B40/($D40-$C40+1),0) -> 0 | G40: =IF(AND(G$12-$B$7>=$C40,G$12-$B$7<=$D40),$B40/($D40-$C40+1),0) -> 0 | H40: =IF(AND(H$12-$B$7>=$C40,H$12-$B$7<=$D40),$B40/($D40-$C40+1),0) -> 0 | I40: =IF(AND(I$12-$B$7>=$C40,I$12-$B$7<=$D40),$B40/($D40-$C40+1),0) -> 0 | J40: =IF(AND(J$12-$B$7>=$C40,J$12-$B$7<=$D40),$B40/($D40-$C40+1),0) -> 0 | K40: =IF(AND(K$12-$B$7>=$C40,K$12-$B$7<=$D40),$B40/($D40-$C40+1),0) -> 0 | L40: =IF(AND(L$12-$B$7>=$C40,L$12-$B$7<=$D40),$B40/($D40-$C40+1),0) -> 0 | M40: =IF(AND(M$12-$B$7>=$C40,M$12-$B$7<=$D40),$B40/($D40-$C40+1),0) -> 0 | ... BG40: =IF(AND(BG$12-$B$7>=$C40,BG$12-$B$7<=$D40),$B40/($D40-$C40+1),0) -> 0
A41: Insulated opaque wall, street walls | B41: ='Hard Costs'!$G$74 -> 148500 | C41: 10 | D41: 15 | F41: =IF(AND(F$12-$B$7>=$C41,F$12-$B$7<=$D41),$B41/($D41-$C41+1),0) -> 0 | G41: =IF(AND(G$12-$B$7>=$C41,G$12-$B$7<=$D41),$B41/($D41-$C41+1),0) -> 0 | H41: =IF(AND(H$12-$B$7>=$C41,H$12-$B$7<=$D41),$B41/($D41-$C41+1),0) -> 0 | I41: =IF(AND(I$12-$B$7>=$C41,I$12-$B$7<=$D41),$B41/($D41-$C41+1),0) -> 0 | J41: =IF(AND(J$12-$B$7>=$C41,J$12-$B$7<=$D41),$B41/($D41-$C41+1),0) -> 0 | K41: =IF(AND(K$12-$B$7>=$C41,K$12-$B$7<=$D41),$B41/($D41-$C41+1),0) -> 0 | L41: =IF(AND(L$12-$B$7>=$C41,L$12-$B$7<=$D41),$B41/($D41-$C41+1),0) -> 0 | M41: =IF(AND(M$12-$B$7>=$C41,M$12-$B$7<=$D41),$B41/($D41-$C41+1),0) -> 0 | ... BG41: =IF(AND(BG$12-$B$7>=$C41,BG$12-$B$7<=$D41),$B41/($D41-$C41+1),0) -> 0
A42: Lot-line and party walls | B42: ='Hard Costs'!$G$75 -> 448140 | C42: 8 | D42: 13 | F42: =IF(AND(F$12-$B$7>=$C42,F$12-$B$7<=$D42),$B42/($D42-$C42+1),0) -> 0 | G42: =IF(AND(G$12-$B$7>=$C42,G$12-$B$7<=$D42),$B42/($D42-$C42+1),0) -> 0 | H42: =IF(AND(H$12-$B$7>=$C42,H$12-$B$7<=$D42),$B42/($D42-$C42+1),0) -> 0 | I42: =IF(AND(I$12-$B$7>=$C42,I$12-$B$7<=$D42),$B42/($D42-$C42+1),0) -> 0 | J42: =IF(AND(J$12-$B$7>=$C42,J$12-$B$7<=$D42),$B42/($D42-$C42+1),0) -> 0 | K42: =IF(AND(K$12-$B$7>=$C42,K$12-$B$7<=$D42),$B42/($D42-$C42+1),0) -> 0 | L42: =IF(AND(L$12-$B$7>=$C42,L$12-$B$7<=$D42),$B42/($D42-$C42+1),0) -> 0 | M42: =IF(AND(M$12-$B$7>=$C42,M$12-$B$7<=$D42),$B42/($D42-$C42+1),0) -> 0 | ... BG42: =IF(AND(BG$12-$B$7>=$C42,BG$12-$B$7<=$D42),$B42/($D42-$C42+1),0) -> 0
A43: Façade fins (none in this design) | B43: ='Hard Costs'!$G$76 -> 0 | C43: 14 | D43: 16 | F43: =IF(AND(F$12-$B$7>=$C43,F$12-$B$7<=$D43),$B43/($D43-$C43+1),0) -> 0 | G43: =IF(AND(G$12-$B$7>=$C43,G$12-$B$7<=$D43),$B43/($D43-$C43+1),0) -> 0 | H43: =IF(AND(H$12-$B$7>=$C43,H$12-$B$7<=$D43),$B43/($D43-$C43+1),0) -> 0 | I43: =IF(AND(I$12-$B$7>=$C43,I$12-$B$7<=$D43),$B43/($D43-$C43+1),0) -> 0 | J43: =IF(AND(J$12-$B$7>=$C43,J$12-$B$7<=$D43),$B43/($D43-$C43+1),0) -> 0 | K43: =IF(AND(K$12-$B$7>=$C43,K$12-$B$7<=$D43),$B43/($D43-$C43+1),0) -> 0 | L43: =IF(AND(L$12-$B$7>=$C43,L$12-$B$7<=$D43),$B43/($D43-$C43+1),0) -> 0 | M43: =IF(AND(M$12-$B$7>=$C43,M$12-$B$7<=$D43),$B43/($D43-$C43+1),0) -> 0 | ... BG43: =IF(AND(BG$12-$B$7>=$C43,BG$12-$B$7<=$D43),$B43/($D43-$C43+1),0) -> 0
A44: Roofing, waterproofing and flashing | B44: ='Hard Costs'!$G$77 -> 192014 | C44: 11 | D44: 13 | F44: =IF(AND(F$12-$B$7>=$C44,F$12-$B$7<=$D44),$B44/($D44-$C44+1),0) -> 0 | G44: =IF(AND(G$12-$B$7>=$C44,G$12-$B$7<=$D44),$B44/($D44-$C44+1),0) -> 0 | H44: =IF(AND(H$12-$B$7>=$C44,H$12-$B$7<=$D44),$B44/($D44-$C44+1),0) -> 0 | I44: =IF(AND(I$12-$B$7>=$C44,I$12-$B$7<=$D44),$B44/($D44-$C44+1),0) -> 0 | J44: =IF(AND(J$12-$B$7>=$C44,J$12-$B$7<=$D44),$B44/($D44-$C44+1),0) -> 0 | K44: =IF(AND(K$12-$B$7>=$C44,K$12-$B$7<=$D44),$B44/($D44-$C44+1),0) -> 0 | L44: =IF(AND(L$12-$B$7>=$C44,L$12-$B$7<=$D44),$B44/($D44-$C44+1),0) -> 0 | M44: =IF(AND(M$12-$B$7>=$C44,M$12-$B$7<=$D44),$B44/($D44-$C44+1),0) -> 0 | ... BG44: =IF(AND(BG$12-$B$7>=$C44,BG$12-$B$7<=$D44),$B44/($D44-$C44+1),0) -> 0
...

Sheet Hard Costs
A1: 246 South 2nd Street · Hard Cost Budget · Base
A2: 246 South 2nd Street on its own 3,100 sf lot in R6 with a commercial overlay: 8 stories at 85 ft (13'-11" ground floor, 11 ft 2nd floor, 10 ft above), plus a cellar and a private roof. 9 condos (8 market-rate and one affordable homeownership unit), 6,879 sellable sf; commercial on the 1st and 2nd floors (4,333 sf sellable) plus 1,857 sf in the cellar; Zone Green (ULEB) 5% exclusion; no air rights or certificates; all-electric.
A3: Blue cells are inputs. Black cells are formulas. Use the + / - buttons at the left edge to collapse the input blocks. Rates carry over from the 725 Grand budget as planning placeholders, not bids. Areas and lengths are measured from the 246 South 2nd Street floor area model (claude.ai artifact), October 18 2026.
A5: KEY AREAS
B6: Gross floor area above grade | C6: =$C$15 -> 14518 | D6: gsf | J6: Seven enclosed floors from the floor area model (see the formula row below).
B7: Cellar | C7: 3060 | D7: sf | J7: Full lot footprint (25 x 120 ft with the 30 ft wide rear 20 ft), less the lot-line offsets.
B8: Cellar depth | C8: 12 | D8: ft | J8: Cellar floor-to-floor, from the model. Used for the excavation volume.
B9: Commercial at grade (1st floor), sellable | C9: 1717 | D9: sf | J9: Model: sellable commercial on the 1st floor (2,344 gross less the lobby, core, corridor and 450 sf parking/loading).
B10: Net sellable residential | C10: =D34 -> 6879 | D10: sf | J10: Total of the unit mix below (offering-plan sf from the model).
B11: Common areas and core | C11: 2855 | D11: sf | J11: Gross above grade less residential and commercial sellable, less 450 sf parking: lobby, corridors, core, light-well walls and mechanical.
B12: Condo units | C12: =C34 -> 9 | D12: units | J12: Total of the unit mix below.
B13: Outer perimeter, all floors above grade | C13: 1810 | D13: Lf | J13: Model: 1st 239, 2nd 299, 4th-6th 230 each, 7th 212, 8th 171 Lf, plus about 40 Lf of light-well walls on floors 4-8.
B14: Rated walls around units | C14: 330 | D14: Lf | J14: Estimate: about 75 Lf of corridor and demising wall on each of floors 4-7, 30 Lf on the full-floor penthouse (8).
B15: Gross floor area above grade (formula) | C15: 14518 | D15: gsf | J15: Model: 1st 2,344 + 2nd 3,060 + 4th 2,035 + 5th 2,023 + 6th 2,020 + 7th 1,728 + 8th 1,308. The 3rd floor has no enclosed gross area in the model (2,467 sf common terrace and an amenity room).
B16: Street, rear and light-well wall area | C16: 5500 | D16: sf | J16: Street wall about 2,100 sf (to the 65 ft base plus the setback walls), rear walls about 1,900 sf, light-well walls about 1,500 sf.
B17: Cellar commercial and community facility area | C17: 1857 | D17: sf | J17: Model: 1,556 sf commercial plus 301 sf community facility in the cellar, sold with the commercial condo. Not zoning floor area.
B18: Stories above grade | C18: 8 | D18: floors | J18: Ground + 7, counting the 3rd-floor terrace level. Private roof above, no elevator stop there.
B19: Dormers | C19: 78 | D19: sf | J19: Model: one 7th-floor dormer in the street setback, 12'-4" x 6'-4" (ZR 23-413).
B20: Glazing share of street-facing wall | C20: 0.4 | D20: % | J20: A modest glass ratio is the cheapest way to meet the ULEB energy target that Zone Green needs.
B21: Hard-cost sensitivity adjustment | C21: 0 | D21: % | J21: Normally 0%. Scales the hard cost up or down, for testing (the OM sensitivity table uses it). Applies to the owner budget too.
B22: Commercial, 2nd floor, sellable | C22: 2616 | D22: sf | J22: Model: the full 2nd floor (3,060 gross less the 444 sf rear terrace).
B23: Owner's hard-cost budget | C23: 450 | D23: $ / gsf | J23: Owner, Oct 2026: $450 per gross sf, all in (trades, general conditions, fee and contingency).
B24: Area the owner's $ / gsf applies to | C24: =$C$6 -> 14518 | D24: gsf | J24: Gross above grade, the same basis as the 725 Grand $ / gsf measure. Owner to confirm: to include the 3,060 sf cellar, change this to =$C$6+$C$7 (+$1.38M).
B25: Use the owner's budget (1) or the line items (0) | C25: 1 | J25: 1: total hard cost = owner's budget; the line items stay as the detail and the gap goes on the adjustment line. 0: line items only.
A27: UNIT MIX
B28: Unit type | C28: Units | D28: Net sf per unit | E28: Partitions per unit (Lf) | F28: Interior doors per unit | G28: Baths per unit | J28: Notes
B29: Affordable 1-bedroom, floor 4 (4F), for sale | C29: 1 | D29: 858 | E29: 50 | F29: 5 | G29: 1 | J29: Affordable homeownership unit. Street side.
B30: 1-bedroom, rear, floors 4-7 (4R, 5R, 6R, 7R) | C30: 4 | D30: 718.75 | E30: 50 | F30: 5 | G30: 1 | J30: Model: 714, 719, 719 and 723 sf; each with a rear balcony.
B31: 2-bedroom, street, floors 5-6 (5F, 6F) | C31: 2 | D31: 858 | E31: 70 | F31: 6 | G31: 2 | J31: Two baths.
B32: Studio with street terrace, floor 7 (7F) | C32: 1 | D32: 567 | E32: 25 | F32: 3 | G32: 1 | J32: 292 sf private terrace on the 15 ft setback.
B33: Full-floor penthouse, floor 8, 2 bedrooms + private roof | C33: 1 | D33: 863 | E33: 80 | F33: 7 | G33: 2 | J33: Setback terrace and balcony (431 sf) plus a 1,505 sf private roof by a private stair.
B34: Total | C34: =SUM(C29:C33) -> 9 | D34: =SUMPRODUCT($C$29:$C$33,D29:D33) -> 6879 | E34: =SUMPRODUCT($C$29:$C$33,E29:E33) -> 495 | F34: =SUMPRODUCT($C$29:$C$33,F29:F33) -> 47 | G34: =SUMPRODUCT($C$29:$C$33,G29:G33) -> 12 | H34: 0 | J34: Units, total sellable sf, partition Lf, interior doors and baths. No duplex or mezzanine units.
A36: ZONING FLOOR AREA CHECK
B37: Lot area, 246 South 2nd Street | C37: 3100 | D37: sf | J37: 25 x 120 ft; the rear 20 ft is 30 ft wide. From the model.
B38: Total floor area ratio (R6 with qualifying affordable housing) | C38: 4.8 | D38: FAR | J38: Model zoning input. Counsel to confirm.
B39: Maximum zoning floor area, all uses | C39: =C37*C38 -> 14880 | D39: sf
B40: Market-rate residential floor area ratio | C40: 2.2 | D40: FAR | J40: Model zoning input.
B41: Market-rate residential allowed | C41: =C37*C40 -> 6820 | D41: sf
B42: Zone Green (ULEB) exclusion, taken off residential | C42: 627 | D42: sf | J42: Model: 5% of the 12,538 sf zoning floor area above grade. Needs an ultra low energy (Passive House level) building; without it the 5% is lost.
B43: Counted: market-rate residential, after the exclusion | C43: 6819 | D43: sf | J43: Model, floors 4-8 plus the core on the 1st floor.
...

Sheet Soft Costs
A1: 246 South 2nd Street · Soft Cost Budget
A2: Base: section 1 is the land (acquisition, kept apart from the soft-cost totals); section 2 is construction-period soft costs; section 3 is sponsor wind-down. 8 stories at 85 ft, 9 condos plus a commercial condo, no air rights or certificates.
A3: Blue cells are inputs: change them and every total updates. Black cells are formulas. Rates carry over from the 725 Grand budget unless noted. Every figure is a planning placeholder to be verified.
A5: KEY INPUTS
B6: Total hard cost | C6: ='Hard Costs'!$G$121 -> 6533100 | D6: $ | J6: Linked to the total on the Hard Costs sheet (green = link). Drives the development fee and the warranty reserve.
B7: Land purchase price, 246 South 2nd | C7: 4000000 | D7: $ | J7: Owner, Oct 2026: $4,000,000.
B8: Gross floor area above grade | C8: ='Hard Costs'!$C$6 -> 14518 | D8: gsf | J8: Linked to the Hard Costs sheet (green).
B9: Cellar | C9: ='Hard Costs'!$C$7 -> 3060 | D9: sf | J9: Linked to the Hard Costs sheet (green).
B10: Gross floor area including cellar | C10: =$C$8+$C$9 -> 17578 | D10: gsf | J10: Basis for design and inspection fees.
B11: Condo units | C11: ='Hard Costs'!$C$12 -> 9 | D11: units | J11: Linked to the Hard Costs sheet (green).
B12: Project length | C12: =Finance!$B$10 -> 32 | D12: months | J12: Linked to the Finance sheet (green). Purchase to final unit closing.
B13: Construction period | C13: =Finance!$B$7 -> 20 | D13: months | J13: Linked to the Finance sheet (green). Ground-breaking to completion (TCO). Placeholder until the Gantt chart sets it. Drives builder's risk and construction-period liability insurance.
B14: Owner tax-holding period | C14: 36 | D14: months | J14: Purchase until the condo plan is effective and taxes pass to the condominium. Set to your expected date; 36 months is conservative.
B15: Construction loan amount | C15: =Finance!$B$38 -> 9303306.9 | D15: $ | J15: Linked to the Finance sheet (green). Deck model: 70% of total project cost. Basis for the mortgage recording tax.
B16: Inclusionary Housing certificates purchased | C16: 0 | D16: sf | J16: None: the affordable floor area is the on-site affordable unit (4F).
A18: Section | B18: Line item | C18: Basis | D18: Basis unit | E18: Rate | F18: Rate basis | G18: Total ($) | H18: % of hard | I18: In deck model? | J18: Notes
A19: 1 · ACQUISITION: LAND (shown apart from the soft costs)
A20: Acquisition | B20: Land purchase, 246 South 2nd | C20: =$C$7 -> 4000000 | D20: $ price | E20: 1 | F20: % of price | G20: =C20*E20 -> 4000000 | H20: =G20/$C$6 -> 0.61226676 | I20: Yes | J20: Owner: $4.0M. Change it in the key inputs above. Paid at closing.
A21: Land | G21: =SUM(G20:G20) -> 4000000 | H21: =G21/$C$6 -> 0.61226676
A23: Acquisition | B23: Inclusionary Housing certificates (none) | C23: =$C$16 -> 0 | D23: sf | E23: 200 | F23: $ / sf | G23: =C23*E23 -> 0 | H23: =G23/$C$6 -> 0 | I23: No | J23: Not needed for this design.
A24: IH certificates | G24: =SUM(G23:G23) -> 0 | H24: =G24/$C$6 -> 0
A26: TOTAL ACQUISITION | G26: =G21+G24 -> 4000000 | H26: =G26/$C$6 -> 0.61226676
A28: 2 · CONSTRUCTION-PERIOD SOFT COSTS
A29: Construction | B29: Architecture, structural and MEP engineering | C29: 1 | D29: allowance | E29: 300000 | F29: lump sum | G29: =C29*E29 -> 300000 | H29: =G29/$C$6 -> 0.045920007 | I29: Yes | J29: Owner's 725 Grand figure carried over. Architect of record plus structural, MEP and fire protection engineering through construction administration; the owner's in-house design keeps it below a full-service fee.
A30: Construction | B30: Interior design | C30: 1 | D30: allowance | E30: 40000 | F30: lump sum | G30: =C30*E30 -> 40000 | H30: =G30/$C$6 -> 0.0061226676 | I30: No | J30: Owner's figure, Oct 2026. The deck model has no interior design line yet.
A31: Construction | B31: Expediting, DOB and utility filing fees | C31: 1 | D31: allowance | E31: 45000 | F31: lump sum | G31: =C31*E31 -> 45000 | H31: =G31/$C$6 -> 0.0068880011 | I31: Yes | J31: Owner's figure, Oct 2026.
A32: Construction | B32: Surveys, controlled and special inspections | C32: =$C$10 -> 17578 | D32: gsf | E32: 3.5 | F32: $ / gsf | G32: =C32*E32 -> 61523 | H32: =G32/$C$6 -> 0.009417122 | I32: Yes
A33: Construction | B33: Phase I environmental report | C33: 1 | D33: allowance | E33: 5000 | F33: lump sum | G33: =C33*E33 -> 5000 | H33: =G33/$C$6 -> 0.00076533346 | I33: Yes | J33: Owner, Oct 2026: site not expected to be contaminated; a Phase I is the only investigation budgeted.
A34: Construction | B34: Environmental filings (OER), if the lot has an E-designation | C34: 1 | D34: allowance | E34: 0 | F34: lump sum | G34: =C34*E34 -> 0 | H34: =G34/$C$6 -> 0 | I34: No | J34: None carried: confirm on ZoLa whether 246 South 2nd has an E-designation.
A35: Construction | B35: Energy consultant: energy model, ULEB filing and commissioning | C35: 1 | D35: allowance | E35: 30000 | F35: lump sum | G35: =C35*E35 -> 30000 | H35: =G35/$C$6 -> 0.0045920007 | I35: No | J35: Documents the ULEB energy target that the 5% Zone Green exclusion needs (Passive House level performance); energy model and commissioning.
A36: Construction | B36: Builder's risk insurance | C36: =$C$13 -> 20 | D36: months | E36: 50000 | F36: $ / year | G36: =C36*E36/12 -> 83333.333 | H36: =G36/$C$6 -> 0.012755558 | I36: Yes | J36: Property cover for the building under construction, for the construction period. Placeholder: get a quote.
A37: Construction | B37: General liability insurance during construction | C37: =$C$13 -> 20 | D37: months | E37: 150000 | F37: $ / year | G37: =C37*E37/12 -> 250000 | H37: =G37/$C$6 -> 0.038266673 | I37: Yes | J37: Owner, Oct 15 2026: $125,000/yr covered both builder's risk and GL on a smaller project seven years ago; NYC liability rates have risen sharply since. If the GC's own liability policy is billed in general conditions, check this is not counted twice.
A38: Construction | B38: Owner's property and liability insurance after completion | C38: =$C$12-$C$13 -> 12 | D38: months | E38: 30000 | F38: $ / year | G38: =C38*E38/12 -> 30000 | H38: =G38/$C$6 -> 0.0045920007 | I38: No | J38: From completion until the condo plan is effective and units close (project length less construction period). Placeholder: get a quote.
A39: Construction | B39: Real estate taxes during the owner holding period | C39: =$C$14 -> 36 | D39: months | E39: 67000 | F39: $ / year | G39: =C39*E39/12 -> 201000 | H39: =G39/$C$6 -> 0.030766405 | I39: Yes | J39: 725 Grand's $67,000 a year carried over as a placeholder: replace with 246 South 2nd's DOF bill.
A40: Construction | B40: Legal: acquisition and loan | C40: 1 | D40: allowance | E40: 10000 | F40: lump sum | G40: =C40*E40 -> 10000 | H40: =G40/$C$6 -> 0.0015306669 | I40: Yes | J40: No zoning lot merger, air-rights or easement agreements.
A41: Construction | B41: Offering plan (AG filing) and sponsor legal | C41: 1 | D41: allowance | E41: 60000 | F41: lump sum | G41: =C41*E41 -> 60000 | H41: =G41/$C$6 -> 0.0091840015 | I41: Yes | J41: Condominium with 9 residential units and the commercial condo; includes the affordable unit sale documents.
A42: Construction | B42: Title insurance and recording, land purchase | C42: 1 | D42: allowance | E42: 10000 | F42: lump sum | G42: =C42*E42 -> 10000 | H42: =G42/$C$6 -> 0.0015306669 | I42: Yes | J42: Owner's figure, Oct 2026.
A43: Construction | B43: Development fee | C43: =$C$6 -> 6533100 | D43: $ hard cost | E43: 0.03 | F43: % of hard | G43: =C43*E43 -> 195993 | H43: =G43/$C$6 -> 0.03 | I43: Yes | J43: Sponsor's fee.
A44: Construction | B44: Marketing, branding and sales center | C44: =$C$11 -> 9 | D44: units | E44: 6500 | F44: $ / unit | G44: =C44*E44 -> 58500 | H44: =G44/$C$6 -> 0.0089544014 | I44: Yes
A45: Construction | B45: Appraisal, lender inspections and loan closing | C45: 1 | D45: allowance | E45: 95000 | F45: lump sum | G45: =C45*E45 -> 95000 | H45: =G45/$C$6 -> 0.014541336 | I45: Yes | J45: Loan origination fee and interest are financing costs, not included here.
...
